INFO: Starting training:
        Epochs:          5
        Batch size:      1
        Learning rate:   1e-05
        Training size:   796
        Validation size: 88
        Checkpoints:     True
        Device:          cpu
        Images scaling:  0.5
        Mixed Precision: False
Epoch 1/5:   0%|                                                                              | 0/796 [00:00<?, ?img/s]C:\Users\Andrew\anaconda3\envs\unet\lib\site-packages\torch\autocast_mode.py:162: UserWarning: User provided device_type of 'cuda', but CUDA is not available. Disabling
  warnings.warn('User provided device_type of \'cuda\', but CUDA is not available. Disabling')
Epoch 1/5:   0%|                                                                              | 0/796 [00:02<?, ?img/s]
Traceback (most recent call last):
  File "train.py", line 185, in <module>
    train_net(net=net,
  File "train.py", line 93, in train_net
    loss = criterion(masks_pred, true_masks) \
  File "C:\Users\Andrew\anaconda3\envs\unet\lib\site-packages\torch\nn\modules\module.py", line 1110, in _call_impl
    return forward_call(*input, **kwargs)
  File "C:\Users\Andrew\anaconda3\envs\unet\lib\site-packages\torch\nn\modules\loss.py", line 1163, in forward
    return F.cross_entropy(input, target, weight=self.weight,
  File "C:\Users\Andrew\anaconda3\envs\unet\lib\site-packages\torch\nn\functional.py", line 2996, in cross_entropy
    return torch._C._nn.cross_entropy_loss(input, target, weight, _Reduction.get_enum(reduction), ignore_index, label_smoothing)
IndexError: Target 255 is out of bounds.