INFO: Starting training:
        Epochs:          5
        Batch size:      1
        Learning rate:   1e-05
        Training size:   796
        Validation size: 88
        Checkpoints:     True
        Device:          cpu
        Images scaling:  0.5
        Mixed Precision: False
Epoch 1/5:   0%|          | 0/796 [00:01<?, ?img/s]
Traceback (most recent call last):
  File "c:\Users\Andrew\Documents\Research\MPIS\Pytorch-UNet\train.py", line 185, in <module>
    train_net(net=net,
  File "c:\Users\Andrew\Documents\Research\MPIS\Pytorch-UNet\train.py", line 79, in train_net
    for batch in train_loader:
  File "C:\Users\Andrew\anaconda3\lib\site-packages\torch\utils\data\dataloader.py", line 530, in __next__
    data = self._next_data()
  File "C:\Users\Andrew\anaconda3\lib\site-packages\torch\utils\data\dataloader.py", line 1224, in _next_data
    return self._process_data(data)
  File "C:\Users\Andrew\anaconda3\lib\site-packages\torch\utils\data\dataloader.py", line 1250, in _process_data
    data.reraise()
  File "C:\Users\Andrew\anaconda3\lib\site-packages\torch\_utils.py", line 457, in reraise
    raise exception
TypeError: Caught TypeError in DataLoader worker process 0.
Original Traceback (most recent call last):
  File "C:\Users\Andrew\anaconda3\lib\site-packages\PIL\Image.py", line 2751, in fromarray
    mode, rawmode = _fromarray_typemap[typekey]
KeyError: ((1, 1), '|O')
The above exception was the direct cause of the following exception:
Traceback (most recent call last):
  File "C:\Users\Andrew\anaconda3\lib\site-packages\torch\utils\data\_utils\worker.py", line 287, in _worker_loop
    data = fetcher.fetch(index)
  File "C:\Users\Andrew\anaconda3\lib\site-packages\torch\utils\data\_utils\fetch.py", line 49, in fetch
    data = [self.dataset[idx] for idx in possibly_batched_index]
  File "C:\Users\Andrew\anaconda3\lib\site-packages\torch\utils\data\_utils\fetch.py", line 49, in <listcomp>
    data = [self.dataset[idx] for idx in possibly_batched_index]
  File "C:\Users\Andrew\anaconda3\lib\site-packages\torch\utils\data\dataset.py", line 471, in __getitem__
    return self.dataset[self.indices[idx]]
  File "c:\Users\Andrew\Documents\Research\MPIS\Pytorch-UNet\utils\data_loading.py", line 68, in __getitem__
    mask = Image.fromarray(mask)
  File "C:\Users\Andrew\anaconda3\lib\site-packages\PIL\Image.py", line 2753, in fromarray
    raise TypeError("Cannot handle this data type: %s, %s" % typekey) from e
TypeError: Cannot handle this data type: (1, 1), |O